# Utilisation de l'attente (await) dans les blocs catch et finally

En C#, l'utilisation de l'attente (await) dans les blocs catch et finally offre une approche élégante pour gérer les opérations asynchrones tout en prenant en charge la gestion des exceptions et le nettoyage des ressources.

## Méthode avec blocs try-catch
```csharp
static async Task<string> TraitementAvecTryCatch()
{
    try
    {
        // Effectuer une tâche potentiellement risquée
        return "Succès";
    }
    catch (Exception ex)
    {
        await JournaliserErreurs(ex);
        throw;
    }
    finally
    {
        await NettoyerRessources();
    }
}
```

### Explication
- Dans cette méthode, un bloc try-catch est utilisé pour entourer le code susceptible de générer une exception.
- Si une exception est levée dans le bloc try, le contrôle est transféré au bloc catch où la méthode `JournaliserErreurs(ex)` est appelée de manière asynchrone pour enregistrer les erreurs.
- L'instruction `throw` est ensuite utilisée pour propager l'exception, permettant ainsi au code appelant de la gérer.
- Enfin, le bloc finally est toujours exécuté, même en cas d'exception. Dans ce cas, la méthode `NettoyerRessources()` est appelée de manière asynchrone pour effectuer des opérations de nettoyage.

### Exemple complet
```csharp
using System;
using System.Threading.Tasks;

class Program
{
    static async Task Main(string[] args)
    {
        try
        {
            string result = await TraitementAvecTryCatch();
            Console.WriteLine("Résultat du traitement : " + result);
        }
        catch (Exception ex)
        {
            Console.WriteLine("Une erreur s'est produite : " + ex.Message);
        }
    }

    static async Task<string> TraitementAvecTryCatch()
    {
        try
        {
            // Simulation d'une opération risquée
            await Task.Delay(1000); // Attendre 1 seconde
            return "Succès";
        }
        catch (Exception ex)
        {
            // Journaliser l'erreur
            await JournaliserErreurs(ex);
            throw;
        }
        finally
        {
            // Nettoyer les ressources
            await NettoyerRessources();
        }
    }

    static Task JournaliserErreurs(Exception ex)
    {
        // Implémentation de la journalisation des erreurs
        Console.WriteLine("Erreur : " + ex.Message);
        return Task.CompletedTask;
    }

    static Task NettoyerRessources()
    {
        // Implémentation du nettoyage des ressources
        Console.WriteLine("Nettoyage des ressources effectué.");
        return Task.CompletedTask;
    }
}
```

Dans cet exemple complet, une méthode `TraitementAvecTryCatch()` est définie avec un bloc try-catch-finally, démontrant son utilisation pour gérer les exceptions et exécuter des opérations asynchrones de journalisation et de nettoyage des ressources.

## Conclusion
L'attente dans les blocs catch et finally permet une gestion robuste des exceptions et des opérations asynchrones dans les applications C#. En utilisant cette approche, les développeurs peuvent garantir une exécution fluide du code même en présence d'erreurs, tout en assurant la libération appropriée des ressources. Il est cependant important de garder à l'esprit les performances et la gestion des exceptions lors de l'utilisation de cette fonctionnalité.